Workbook
Name ListaCuentas: Cuentas!$B$9:$B$128
Name Finanzas_HistoricoProductos: 'Cálculos'!$B$278:$K$334
Name ListaFiltroCuentas: 'Cálculos'!$T$9:$T$1331
Name Finanzas_GraficoProductos: 'Cálculos'!$E$340:$F$459
Name ListaFiltroProductos: 'Cálculos'!$U$9:$U$1331
Name ListaSubcategorias: 'Configuración'!$E$15:$E$134
Name Finanzas_MesesInversiones: Inversiones!$B$928:$E$946
Name Finanzas_GraficoCiudades: 'Cálculos'!$P$17:$Q$21
Name Finanzas_CalculoMovimientos: 'Cálculos'!$B$9:$N$128
Name Finanzas_CalculoCategorias: 'Cálculos'!$B$151:$F$270
Name ListaProductos: Inversiones!$B$30:$B$149

Sheet Resumen financiero
B2: Resumen financiero
B4: Año | E4: 2026 | G4: Periodo | I4: Todo el año | N4: Cuenta | Q4: Todas
B7: Patrimonio neto | H7: Efectivo | M7: Inversiones | S7: Deuda
B8: =IF(COUNT('Cálculos'!D5)=0,"",SUM(tCuentas[Saldo calculado])+'Cálculos'!D5+'Cálculos'!C5-SUM(tDeudas[Saldo pendiente])) -> 0 | H8: =SUM(tCuentas[Saldo calculado]) -> 0 | M8: ='Cálculos'!D5 -> 0 | S8: =SUM(tDeudas[Saldo pendiente]) -> 0
B12: Ingresos | H12: Gastos propios | N12: Ahorro | T12: Tasa de ahorro
B13: ='Cálculos'!E4 -> 0 | H13: ='Cálculos'!F4 -> 0 | N13: ='Cálculos'!G4 -> 0 | T13: =IF('Cálculos'!H4="",0,'Cálculos'!H4) -> 0
B53: Resumen mensual
B55: Mes | D55: Ingresos | F55: Gastos | H55: Ahorro | J55: Efectivo
B56: =CHOOSE(MONTH('Cálculos'!B135),"ene","feb","mar","abr","may","jun","jul","ago","sep","oct","nov","dic")&" "&YEAR('Cálculos'!B135) -> ene 2026 | D56: =IF(COUNT('Cálculos'!C135)=0,"",'Cálculos'!C135) -> 0 | F56: =IF(COUNT('Cálculos'!D135)=0,"",'Cálculos'!D135) -> 0 | H56: =IF(COUNT('Cálculos'!E135)=0,"",'Cálculos'!E135) -> 0 | J56: =IF(COUNT('Cálculos'!F135)=0,"",'Cálculos'!F135) -> 0
B57: =CHOOSE(MONTH('Cálculos'!B136),"ene","feb","mar","abr","may","jun","jul","ago","sep","oct","nov","dic")&" "&YEAR('Cálculos'!B136) -> feb 2026 | D57: =IF(COUNT('Cálculos'!C136)=0,"",'Cálculos'!C136) | F57: =IF(COUNT('Cálculos'!D136)=0,"",'Cálculos'!D136) | H57: =IF(COUNT('Cálculos'!E136)=0,"",'Cálculos'!E136) | J57: =IF(COUNT('Cálculos'!F136)=0,"",'Cálculos'!F136)
B58: =CHOOSE(MONTH('Cálculos'!B137),"ene","feb","mar","abr","may","jun","jul","ago","sep","oct","nov","dic")&" "&YEAR('Cálculos'!B137) -> mar 2026 | D58: =IF(COUNT('Cálculos'!C137)=0,"",'Cálculos'!C137) | F58: =IF(COUNT('Cálculos'!D137)=0,"",'Cálculos'!D137) | H58: =IF(COUNT('Cálculos'!E137)=0,"",'Cálculos'!E137) | J58: =IF(COUNT('Cálculos'!F137)=0,"",'Cálculos'!F137)
B59: =CHOOSE(MONTH('Cálculos'!B138),"ene","feb","mar","abr","may","jun","jul","ago","sep","oct","nov","dic")&" "&YEAR('Cálculos'!B138) -> abr 2026 | D59: =IF(COUNT('Cálculos'!C138)=0,"",'Cálculos'!C138) | F59: =IF(COUNT('Cálculos'!D138)=0,"",'Cálculos'!D138) | H59: =IF(COUNT('Cálculos'!E138)=0,"",'Cálculos'!E138) | J59: =IF(COUNT('Cálculos'!F138)=0,"",'Cálculos'!F138)
B60: =CHOOSE(MONTH('Cálculos'!B139),"ene","feb","mar","abr","may","jun","jul","ago","sep","oct","nov","dic")&" "&YEAR('Cálculos'!B139) -> may 2026 | D60: =IF(COUNT('Cálculos'!C139)=0,"",'Cálculos'!C139) | F60: =IF(COUNT('Cálculos'!D139)=0,"",'Cálculos'!D139) | H60: =IF(COUNT('Cálculos'!E139)=0,"",'Cálculos'!E139) | J60: =IF(COUNT('Cálculos'!F139)=0,"",'Cálculos'!F139)
B61: =CHOOSE(MONTH('Cálculos'!B140),"ene","feb","mar","abr","may","jun","jul","ago","sep","oct","nov","dic")&" "&YEAR('Cálculos'!B140) -> jun 2026 | D61: =IF(COUNT('Cálculos'!C140)=0,"",'Cálculos'!C140) | F61: =IF(COUNT('Cálculos'!D140)=0,"",'Cálculos'!D140) | H61: =IF(COUNT('Cálculos'!E140)=0,"",'Cálculos'!E140) | J61: =IF(COUNT('Cálculos'!F140)=0,"",'Cálculos'!F140)
B62: =CHOOSE(MONTH('Cálculos'!B141),"ene","feb","mar","abr","may","jun","jul","ago","sep","oct","nov","dic")&" "&YEAR('Cálculos'!B141) -> jul 2026 | D62: =IF(COUNT('Cálculos'!C141)=0,"",'Cálculos'!C141) | F62: =IF(COUNT('Cálculos'!D141)=0,"",'Cálculos'!D141) | H62: =IF(COUNT('Cálculos'!E141)=0,"",'Cálculos'!E141) | J62: =IF(COUNT('Cálculos'!F141)=0,"",'Cálculos'!F141)
B63: =CHOOSE(MONTH('Cálculos'!B142),"ene","feb","mar","abr","may","jun","jul","ago","sep","oct","nov","dic")&" "&YEAR('Cálculos'!B142) -> ago 2026 | D63: =IF(COUNT('Cálculos'!C142)=0,"",'Cálculos'!C142) | F63: =IF(COUNT('Cálculos'!D142)=0,"",'Cálculos'!D142) | H63: =IF(COUNT('Cálculos'!E142)=0,"",'Cálculos'!E142) | J63: =IF(COUNT('Cálculos'!F142)=0,"",'Cálculos'!F142)
B64: =CHOOSE(MONTH('Cálculos'!B143),"ene","feb","mar","abr","may","jun","jul","ago","sep","oct","nov","dic")&" "&YEAR('Cálculos'!B143) -> sep 2026 | D64: =IF(COUNT('Cálculos'!C143)=0,"",'Cálculos'!C143) | F64: =IF(COUNT('Cálculos'!D143)=0,"",'Cálculos'!D143) | H64: =IF(COUNT('Cálculos'!E143)=0,"",'Cálculos'!E143) | J64: =IF(COUNT('Cálculos'!F143)=0,"",'Cálculos'!F143)
B65: =CHOOSE(MONTH('Cálculos'!B144),"ene","feb","mar","abr","may","jun","jul","ago","sep","oct","nov","dic")&" "&YEAR('Cálculos'!B144) -> oct 2026 | D65: =IF(COUNT('Cálculos'!C144)=0,"",'Cálculos'!C144) | F65: =IF(COUNT('Cálculos'!D144)=0,"",'Cálculos'!D144) | H65: =IF(COUNT('Cálculos'!E144)=0,"",'Cálculos'!E144) | J65: =IF(COUNT('Cálculos'!F144)=0,"",'Cálculos'!F144)
B66: =CHOOSE(MONTH('Cálculos'!B145),"ene","feb","mar","abr","may","jun","jul","ago","sep","oct","nov","dic")&" "&YEAR('Cálculos'!B145) -> nov 2026 | D66: =IF(COUNT('Cálculos'!C145)=0,"",'Cálculos'!C145) | F66: =IF(COUNT('Cálculos'!D145)=0,"",'Cálculos'!D145) | H66: =IF(COUNT('Cálculos'!E145)=0,"",'Cálculos'!E145) | J66: =IF(COUNT('Cálculos'!F145)=0,"",'Cálculos'!F145)
B67: =CHOOSE(MONTH('Cálculos'!B146),"ene","feb","mar","abr","may","jun","jul","ago","sep","oct","nov","dic")&" "&YEAR('Cálculos'!B146) -> dic 2026 | D67: =IF(COUNT('Cálculos'!C146)=0,"",'Cálculos'!C146) | F67: =IF(COUNT('Cálculos'!D146)=0,"",'Cálculos'!D146) | H67: =IF(COUNT('Cálculos'!E146)=0,"",'Cálculos'!E146) | J67: =IF(COUNT('Cálculos'!F146)=0,"",'Cálculos'!F146)

Sheet Movimientos
B2: Movimientos
B8: ID | C8: Fecha | D8: Tipo | E8: Concepto | F8: Subcategoría | G8: Origen | H8: Destino | I8: Importe | J8: Recuperable | K8: Localización | L8: Recurrente

Sheet Inversiones
B2: Inversiones
B4: Producto | D4: Todos | K4: Valoración | M4: ='Configuración'!$C$8 -> 46023
B5: Cartera | F5: Capital neto | J5: Resultado
B6: ='Cálculos'!D5 -> 0 | F6: =SUM(tProductos[Aportado neto]) -> 0 | J6: =IF(COUNT('Cálculos'!D5)=0,"",SUM(tProductos[Resultado])) -> 0
B29: ID | C29: Producto | D29: Cuenta | E29: Clase | F29: Fecha base | G29: Unidades base | H29: Coste base | I29: Participaciones | J29: Aportado neto | K29: Valor | L29: Resultado | M29: Rentabilidad | N29: Peso
I30: =IF(OR(B30="",'Configuración'!$C$8<F30),"",G30+SUMIFS(tOperaciones[Participaciones],tOperaciones[Producto],B30,tOperaciones[Tipo],"Compra",tOperaciones[Fecha],">="&F30,tOperaciones[Fecha],"<="&'Configuración'!$C$8)-SUMIFS(tOperaciones[Participaciones],tOperaciones[Producto],B30,tOperaciones[Tipo],"Venta",tOperaciones[Fecha],">="&F30,tOperaciones[Fecha],"<="&'Configuración'!$C$8)) | J30: =IF(OR(B30="",'Configuración'!$C$8<F30),"",H30+SUMIFS(tOperaciones[Importe],tOperaciones[Producto],B30,tOperaciones[Tipo],"Compra",tOperaciones[Fecha],">="&F30,tOperaciones[Fecha],"<="&'Configuración'!$C$8)-SUMIFS(tOperaciones[Importe],tOperaciones[Producto],B30,tOperaciones[Tipo],"Venta",tOperaciones[Fecha],">="&F30,tOperaciones[Fecha],"<="&'Configuración'!$C$8)) | K30: =IF(OR(B30="",COUNT(I30)=0),"",IF(I30=0,0,IF(COUNTIFS(tPrecios[Producto],B30,tPrecios[Fecha],"<="&'Configuración'!$C$8)=0,"",I30*SUMIFS(tPrecios[VL EUR],tPrecios[Producto],B30,tPrecios[Fecha],MAXIFS(tPrecios[Fecha],tPrecios[Producto],B30,tPrecios[Fecha],"<="&'Configuración'!$C$8))))) | L30: =IF(OR(B30="",COUNT(K30)=0),"",K30-J30+SUMIFS(tOperaciones[Importe],tOperaciones[Producto],B30,tOperaciones[Tipo],"Cobro",tOperaciones[Fecha],">="&F30,tOperaciones[Fecha],"<="&'Configuración'!$C$8)) | M30: =IF(OR(B30="",COUNT(L30)=0,H30+SUMIFS(tOperaciones[Importe],tOperaciones[Producto],B30,tOperaciones[Tipo],"Compra",tOperaciones[Fecha],"<="&'Configuración'!$C$8)=0),"",L30/(H30+SUMIFS(tOperaciones[Importe],tOperaciones[Producto],B30,tOperaciones[Tipo],"Compra",tOperaciones[Fecha],"<="&'Configuración'!$C$8))) | N30: =IF(OR(B30="",COUNT(K30)=0,COUNT(tProductos[Valor])<>COUNTA(tProductos[ID]),SUM(tProductos[Valor])=0),"",K30/SUM(tProductos[Valor]))
I31: =IF(OR(B31="",'Configuración'!$C$8<F31),"",G31+SUMIFS(tOperaciones[Participaciones],tOperaciones[Producto],B31,tOperaciones[Tipo],"Compra",tOperaciones[Fecha],">="&F31,tOperaciones[Fecha],"<="&'Configuración'!$C$8)-SUMIFS(tOperaciones[Participaciones],tOperaciones[Producto],B31,tOperaciones[Tipo],"Venta",tOperaciones[Fecha],">="&F31,tOperaciones[Fecha],"<="&'Configuración'!$C$8)) | J31: =IF(OR(B31="",'Configuración'!$C$8<F31),"",H31+SUMIFS(tOperaciones[Importe],tOperaciones[Producto],B31,tOperaciones[Tipo],"Compra",tOperaciones[Fecha],">="&F31,tOperaciones[Fecha],"<="&'Configuración'!$C$8)-SUMIFS(tOperaciones[Importe],tOperaciones[Producto],B31,tOperaciones[Tipo],"Venta",tOperaciones[Fecha],">="&F31,tOperaciones[Fecha],"<="&'Configuración'!$C$8)) | K31: =IF(OR(B31="",COUNT(I31)=0),"",IF(I31=0,0,IF(COUNTIFS(tPrecios[Producto],B31,tPrecios[Fecha],"<="&'Configuración'!$C$8)=0,"",I31*SUMIFS(tPrecios[VL EUR],tPrecios[Producto],B31,tPrecios[Fecha],MAXIFS(tPrecios[Fecha],tPrecios[Producto],B31,tPrecios[Fecha],"<="&'Configuración'!$C$8))))) | L31: =IF(OR(B31="",COUNT(K31)=0),"",K31-J31+SUMIFS(tOperaciones[Importe],tOperaciones[Producto],B31,tOperaciones[Tipo],"Cobro",tOperaciones[Fecha],">="&F31,tOperaciones[Fecha],"<="&'Configuración'!$C$8)) | M31: =IF(OR(B31="",COUNT(L31)=0,H31+SUMIFS(tOperaciones[Importe],tOperaciones[Producto],B31,tOperaciones[Tipo],"Compra",tOperaciones[Fecha],"<="&'Configuración'!$C$8)=0),"",L31/(H31+SUMIFS(tOperaciones[Importe],tOperaciones[Producto],B31,tOperaciones[Tipo],"Compra",tOperaciones[Fecha],"<="&'Configuración'!$C$8))) | N31: =IF(OR(B31="",COUNT(K31)=0,COUNT(tProductos[Valor])<>COUNTA(tProductos[ID]),SUM(tProductos[Valor])=0),"",K31/SUM(tProductos[Valor]))
I32: =IF(OR(B32="",'Configuración'!$C$8<F32),"",G32+SUMIFS(tOperaciones[Participaciones],tOperaciones[Producto],B32,tOperaciones[Tipo],"Compra",tOperaciones[Fecha],">="&F32,tOperaciones[Fecha],"<="&'Configuración'!$C$8)-SUMIFS(tOperaciones[Participaciones],tOperaciones[Producto],B32,tOperaciones[Tipo],"Venta",tOperaciones[Fecha],">="&F32,tOperaciones[Fecha],"<="&'Configuración'!$C$8)) | J32: =IF(OR(B32="",'Configuración'!$C$8<F32),"",H32+SUMIFS(tOperaciones[Importe],tOperaciones[Producto],B32,tOperaciones[Tipo],"Compra",tOperaciones[Fecha],">="&F32,tOperaciones[Fecha],"<="&'Configuración'!$C$8)-SUMIFS(tOperaciones[Importe],tOperaciones[Producto],B32,tOperaciones[Tipo],"Venta",tOperaciones[Fecha],">="&F32,tOperaciones[Fecha],"<="&'Configuración'!$C$8)) | K32: =IF(OR(B32="",COUNT(I32)=0),"",IF(I32=0,0,IF(COUNTIFS(tPrecios[Producto],B32,tPrecios[Fecha],"<="&'Configuración'!$C$8)=0,"",I32*SUMIFS(tPrecios[VL EUR],tPrecios[Producto],B32,tPrecios[Fecha],MAXIFS(tPrecios[Fecha],tPrecios[Producto],B32,tPrecios[Fecha],"<="&'Configuración'!$C$8))))) | L32: =IF(OR(B32="",COUNT(K32)=0),"",K32-J32+SUMIFS(tOperaciones[Importe],tOperaciones[Producto],B32,tOperaciones[Tipo],"Cobro",tOperaciones[Fecha],">="&F32,tOperaciones[Fecha],"<="&'Configuración'!$C$8)) | M32: =IF(OR(B32="",COUNT(L32)=0,H32+SUMIFS(tOperaciones[Importe],tOperaciones[Producto],B32,tOperaciones[Tipo],"Compra",tOperaciones[Fecha],"<="&'Configuración'!$C$8)=0),"",L32/(H32+SUMIFS(tOperaciones[Importe],tOperaciones[Producto],B32,tOperaciones[Tipo],"Compra",tOperaciones[Fecha],"<="&'Configuración'!$C$8))) | N32: =IF(OR(B32="",COUNT(K32)=0,COUNT(tProductos[Valor])<>COUNTA(tProductos[ID]),SUM(tProductos[Valor])=0),"",K32/SUM(tProductos[Valor]))
I33: =IF(OR(B33="",'Configuración'!$C$8<F33),"",G33+SUMIFS(tOperaciones[Participaciones],tOperaciones[Producto],B33,tOperaciones[Tipo],"Compra",tOperaciones[Fecha],">="&F33,tOperaciones[Fecha],"<="&'Configuración'!$C$8)-SUMIFS(tOperaciones[Participaciones],tOperaciones[Producto],B33,tOperaciones[Tipo],"Venta",tOperaciones[Fecha],">="&F33,tOperaciones[Fecha],"<="&'Configuración'!$C$8)) | J33: =IF(OR(B33="",'Configuración'!$C$8<F33),"",H33+SUMIFS(tOperaciones[Importe],tOperaciones[Producto],B33,tOperaciones[Tipo],"Compra",tOperaciones[Fecha],">="&F33,tOperaciones[Fecha],"<="&'Configuración'!$C$8)-SUMIFS(tOperaciones[Importe],tOperaciones[Producto],B33,tOperaciones[Tipo],"Venta",tOperaciones[Fecha],">="&F33,tOperaciones[Fecha],"<="&'Configuración'!$C$8)) | K33: =IF(OR(B33="",COUNT(I33)=0),"",IF(I33=0,0,IF(COUNTIFS(tPrecios[Producto],B33,tPrecios[Fecha],"<="&'Configuración'!$C$8)=0,"",I33*SUMIFS(tPrecios[VL EUR],tPrecios[Producto],B33,tPrecios[Fecha],MAXIFS(tPrecios[Fecha],tPrecios[Producto],B33,tPrecios[Fecha],"<="&'Configuración'!$C$8))))) | L33: =IF(OR(B33="",COUNT(K33)=0),"",K33-J33+SUMIFS(tOperaciones[Importe],tOperaciones[Producto],B33,tOperaciones[Tipo],"Cobro",tOperaciones[Fecha],">="&F33,tOperaciones[Fecha],"<="&'Configuración'!$C$8)) | M33: =IF(OR(B33="",COUNT(L33)=0,H33+SUMIFS(tOperaciones[Importe],tOperaciones[Producto],B33,tOperaciones[Tipo],"Compra",tOperaciones[Fecha],"<="&'Configuración'!$C$8)=0),"",L33/(H33+SUMIFS(tOperaciones[Importe],tOperaciones[Producto],B33,tOperaciones[Tipo],"Compra",tOperaciones[Fecha],"<="&'Configuración'!$C$8))) | N33: =IF(OR(B33="",COUNT(K33)=0,COUNT(tProductos[Valor])<>COUNTA(tProductos[ID]),SUM(tProductos[Valor])=0),"",K33/SUM(tProductos[Valor]))
I34: =IF(OR(B34="",'Configuración'!$C$8<F34),"",G34+SUMIFS(tOperaciones[Participaciones],tOperaciones[Producto],B34,tOperaciones[Tipo],"Compra",tOperaciones[Fecha],">="&F34,tOperaciones[Fecha],"<="&'Configuración'!$C$8)-SUMIFS(tOperaciones[Participaciones],tOperaciones[Producto],B34,tOperaciones[Tipo],"Venta",tOperaciones[Fecha],">="&F34,tOperaciones[Fecha],"<="&'Configuración'!$C$8)) | J34: =IF(OR(B34="",'Configuración'!$C$8<F34),"",H34+SUMIFS(tOperaciones[Importe],tOperaciones[Producto],B34,tOperaciones[Tipo],"Compra",tOperaciones[Fecha],">="&F34,tOperaciones[Fecha],"<="&'Configuración'!$C$8)-SUMIFS(tOperaciones[Importe],tOperaciones[Producto],B34,tOperaciones[Tipo],"Venta",tOperaciones[Fecha],">="&F34,tOperaciones[Fecha],"<="&'Configuración'!$C$8)) | K34: =IF(OR(B34="",COUNT(I34)=0),"",IF(I34=0,0,IF(COUNTIFS(tPrecios[Producto],B34,tPrecios[Fecha],"<="&'Configuración'!$C$8)=0,"",I34*SUMIFS(tPrecios[VL EUR],tPrecios[Producto],B34,tPrecios[Fecha],MAXIFS(tPrecios[Fecha],tPrecios[Producto],B34,tPrecios[Fecha],"<="&'Configuración'!$C$8))))) | L34: =IF(OR(B34="",COUNT(K34)=0),"",K34-J34+SUMIFS(tOperaciones[Importe],tOperaciones[Producto],B34,tOperaciones[Tipo],"Cobro",tOperaciones[Fecha],">="&F34,tOperaciones[Fecha],"<="&'Configuración'!$C$8)) | M34: =IF(OR(B34="",COUNT(L34)=0,H34+SUMIFS(tOperaciones[Importe],tOperaciones[Producto],B34,tOperaciones[Tipo],"Compra",tOperaciones[Fecha],"<="&'Configuración'!$C$8)=0),"",L34/(H34+SUMIFS(tOperaciones[Importe],tOperaciones[Producto],B34,tOperaciones[Tipo],"Compra",tOperaciones[Fecha],"<="&'Configuración'!$C$8))) | N34: =IF(OR(B34="",COUNT(K34)=0,COUNT(tProductos[Valor])<>COUNTA(tProductos[ID]),SUM(tProductos[Valor])=0),"",K34/SUM(tProductos[Valor]))
I35: =IF(OR(B35="",'Configuración'!$C$8<F35),"",G35+SUMIFS(tOperaciones[Participaciones],tOperaciones[Producto],B35,tOperaciones[Tipo],"Compra",tOperaciones[Fecha],">="&F35,tOperaciones[Fecha],"<="&'Configuración'!$C$8)-SUMIFS(tOperaciones[Participaciones],tOperaciones[Producto],B35,tOperaciones[Tipo],"Venta",tOperaciones[Fecha],">="&F35,tOperaciones[Fecha],"<="&'Configuración'!$C$8)) | J35: =IF(OR(B35="",'Configuración'!$C$8<F35),"",H35+SUMIFS(tOperaciones[Importe],tOperaciones[Producto],B35,tOperaciones[Tipo],"Compra",tOperaciones[Fecha],">="&F35,tOperaciones[Fecha],"<="&'Configuración'!$C$8)-SUMIFS(tOperaciones[Importe],tOperaciones[Producto],B35,tOperaciones[Tipo],"Venta",tOperaciones[Fecha],">="&F35,tOperaciones[Fecha],"<="&'Configuración'!$C$8)) | K35: =IF(OR(B35="",COUNT(I35)=0),"",IF(I35=0,0,IF(COUNTIFS(tPrecios[Producto],B35,tPrecios[Fecha],"<="&'Configuración'!$C$8)=0,"",I35*SUMIFS(tPrecios[VL EUR],tPrecios[Producto],B35,tPrecios[Fecha],MAXIFS(tPrecios[Fecha],tPrecios[Producto],B35,tPrecios[Fecha],"<="&'Configuración'!$C$8))))) | L35: =IF(OR(B35="",COUNT(K35)=0),"",K35-J35+SUMIFS(tOperaciones[Importe],tOperaciones[Producto],B35,tOperaciones[Tipo],"Cobro",tOperaciones[Fecha],">="&F35,tOperaciones[Fecha],"<="&'Configuración'!$C$8)) | M35: =IF(OR(B35="",COUNT(L35)=0,H35+SUMIFS(tOperaciones[Importe],tOperaciones[Producto],B35,tOperaciones[Tipo],"Compra",tOperaciones[Fecha],"<="&'Configuración'!$C$8)=0),"",L35/(H35+SUMIFS(tOperaciones[Importe],tOperaciones[Producto],B35,tOperaciones[Tipo],"Compra",tOperaciones[Fecha],"<="&'Configuración'!$C$8))) | N35: =IF(OR(B35="",COUNT(K35)=0,COUNT(tProductos[Valor])<>COUNTA(tProductos[ID]),SUM(tProductos[Valor])=0),"",K35/SUM(tProductos[Valor]))
I36: =IF(OR(B36="",'Configuración'!$C$8<F36),"",G36+SUMIFS(tOperaciones[Participaciones],tOperaciones[Producto],B36,tOperaciones[Tipo],"Compra",tOperaciones[Fecha],">="&F36,tOperaciones[Fecha],"<="&'Configuración'!$C$8)-SUMIFS(tOperaciones[Participaciones],tOperaciones[Producto],B36,tOperaciones[Tipo],"Venta",tOperaciones[Fecha],">="&F36,tOperaciones[Fecha],"<="&'Configuración'!$C$8)) | J36: =IF(OR(B36="",'Configuración'!$C$8<F36),"",H36+SUMIFS(tOperaciones[Importe],tOperaciones[Producto],B36,tOperaciones[Tipo],"Compra",tOperaciones[Fecha],">="&F36,tOperaciones[Fecha],"<="&'Configuración'!$C$8)-SUMIFS(tOperaciones[Importe],tOperaciones[Producto],B36,tOperaciones[Tipo],"Venta",tOperaciones[Fecha],">="&F36,tOperaciones[Fecha],"<="&'Configuración'!$C$8)) | K36: =IF(OR(B36="",COUNT(I36)=0),"",IF(I36=0,0,IF(COUNTIFS(tPrecios[Producto],B36,tPrecios[Fecha],"<="&'Configuración'!$C$8)=0,"",I36*SUMIFS(tPrecios[VL EUR],tPrecios[Producto],B36,tPrecios[Fecha],MAXIFS(tPrecios[Fecha],tPrecios[Producto],B36,tPrecios[Fecha],"<="&'Configuración'!$C$8))))) | L36: =IF(OR(B36="",COUNT(K36)=0),"",K36-J36+SUMIFS(tOperaciones[Importe],tOperaciones[Producto],B36,tOperaciones[Tipo],"Cobro",tOperaciones[Fecha],">="&F36,tOperaciones[Fecha],"<="&'Configuración'!$C$8)) | M36: =IF(OR(B36="",COUNT(L36)=0,H36+SUMIFS(tOperaciones[Importe],tOperaciones[Producto],B36,tOperaciones[Tipo],"Compra",tOperaciones[Fecha],"<="&'Configuración'!$C$8)=0),"",L36/(H36+SUMIFS(tOperaciones[Importe],tOperaciones[Producto],B36,tOperaciones[Tipo],"Compra",tOperaciones[Fecha],"<="&'Configuración'!$C$8))) | N36: =IF(OR(B36="",COUNT(K36)=0,COUNT(tProductos[Valor])<>COUNTA(tProductos[ID]),SUM(tProductos[Valor])=0),"",K36/SUM(tProductos[Valor]))
I37: =IF(OR(B37="",'Configuración'!$C$8<F37),"",G37+SUMIFS(tOperaciones[Participaciones],tOperaciones[Producto],B37,tOperaciones[Tipo],"Compra",tOperaciones[Fecha],">="&F37,tOperaciones[Fecha],"<="&'Configuración'!$C$8)-SUMIFS(tOperaciones[Participaciones],tOperaciones[Producto],B37,tOperaciones[Tipo],"Venta",tOperaciones[Fecha],">="&F37,tOperaciones[Fecha],"<="&'Configuración'!$C$8)) | J37: =IF(OR(B37="",'Configuración'!$C$8<F37),"",H37+SUMIFS(tOperaciones[Importe],tOperaciones[Producto],B37,tOperaciones[Tipo],"Compra",tOperaciones[Fecha],">="&F37,tOperaciones[Fecha],"<="&'Configuración'!$C$8)-SUMIFS(tOperaciones[Importe],tOperaciones[Producto],B37,tOperaciones[Tipo],"Venta",tOperaciones[Fecha],">="&F37,tOperaciones[Fecha],"<="&'Configuración'!$C$8)) | K37: =IF(OR(B37="",COUNT(I37)=0),"",IF(I37=0,0,IF(COUNTIFS(tPrecios[Producto],B37,tPrecios[Fecha],"<="&'Configuración'!$C$8)=0,"",I37*SUMIFS(tPrecios[VL EUR],tPrecios[Producto],B37,tPrecios[Fecha],MAXIFS(tPrecios[Fecha],tPrecios[Producto],B37,tPrecios[Fecha],"<="&'Configuración'!$C$8))))) | L37: =IF(OR(B37="",COUNT(K37)=0),"",K37-J37+SUMIFS(tOperaciones[Importe],tOperaciones[Producto],B37,tOperaciones[Tipo],"Cobro",tOperaciones[Fecha],">="&F37,tOperaciones[Fecha],"<="&'Configuración'!$C$8)) | M37: =IF(OR(B37="",COUNT(L37)=0,H37+SUMIFS(tOperaciones[Importe],tOperaciones[Producto],B37,tOperaciones[Tipo],"Compra",tOperaciones[Fecha],"<="&'Configuración'!$C$8)=0),"",L37/(H37+SUMIFS(tOperaciones[Importe],tOperaciones[Producto],B37,tOperaciones[Tipo],"Compra",tOperaciones[Fecha],"<="&'Configuración'!$C$8))) | N37: =IF(OR(B37="",COUNT(K37)=0,COUNT(tProductos[Valor])<>COUNTA(tProductos[ID]),SUM(tProductos[Valor])=0),"",K37/SUM(tProductos[Valor]))
I38: =IF(OR(B38="",'Configuración'!$C$8<F38),"",G38+SUMIFS(tOperaciones[Participaciones],tOperaciones[Producto],B38,tOperaciones[Tipo],"Compra",tOperaciones[Fecha],">="&F38,tOperaciones[Fecha],"<="&'Configuración'!$C$8)-SUMIFS(tOperaciones[Participaciones],tOperaciones[Producto],B38,tOperaciones[Tipo],"Venta",tOperaciones[Fecha],">="&F38,tOperaciones[Fecha],"<="&'Configuración'!$C$8)) | J38: =IF(OR(B38="",'Configuración'!$C$8<F38),"",H38+SUMIFS(tOperaciones[Importe],tOperaciones[Producto],B38,tOperaciones[Tipo],"Compra",tOperaciones[Fecha],">="&F38,tOperaciones[Fecha],"<="&'Configuración'!$C$8)-SUMIFS(tOperaciones[Importe],tOperaciones[Producto],B38,tOperaciones[Tipo],"Venta",tOperaciones[Fecha],">="&F38,tOperaciones[Fecha],"<="&'Configuración'!$C$8)) | K38: =IF(OR(B38="",COUNT(I38)=0),"",IF(I38=0,0,IF(COUNTIFS(tPrecios[Producto],B38,tPrecios[Fecha],"<="&'Configuración'!$C$8)=0,"",I38*SUMIFS(tPrecios[VL EUR],tPrecios[Producto],B38,tPrecios[Fecha],MAXIFS(tPrecios[Fecha],tPrecios[Producto],B38,tPrecios[Fecha],"<="&'Configuración'!$C$8))))) | L38: =IF(OR(B38="",COUNT(K38)=0),"",K38-J38+SUMIFS(tOperaciones[Importe],tOperaciones[Producto],B38,tOperaciones[Tipo],"Cobro",tOperaciones[Fecha],">="&F38,tOperaciones[Fecha],"<="&'Configuración'!$C$8)) | M38: =IF(OR(B38="",COUNT(L38)=0,H38+SUMIFS(tOperaciones[Importe],tOperaciones[Producto],B38,tOperaciones[Tipo],"Compra",tOperaciones[Fecha],"<="&'Configuración'!$C$8)=0),"",L38/(H38+SUMIFS(tOperaciones[Importe],tOperaciones[Producto],B38,tOperaciones[Tipo],"Compra",tOperaciones[Fecha],"<="&'Configuración'!$C$8))) | N38: =IF(OR(B38="",COUNT(K38)=0,COUNT(tProductos[Valor])<>COUNTA(tProductos[ID]),SUM(tProductos[Valor])=0),"",K38/SUM(tProductos[Valor]))
I39: =IF(OR(B39="",'Configuración'!$C$8<F39),"",G39+SUMIFS(tOperaciones[Participaciones],tOperaciones[Producto],B39,tOperaciones[Tipo],"Compra",tOperaciones[Fecha],">="&F39,tOperaciones[Fecha],"<="&'Configuración'!$C$8)-SUMIFS(tOperaciones[Participaciones],tOperaciones[Producto],B39,tOperaciones[Tipo],"Venta",tOperaciones[Fecha],">="&F39,tOperaciones[Fecha],"<="&'Configuración'!$C$8)) | J39: =IF(OR(B39="",'Configuración'!$C$8<F39),"",H39+SUMIFS(tOperaciones[Importe],tOperaciones[Producto],B39,tOperaciones[Tipo],"Compra",tOperaciones[Fecha],">="&F39,tOperaciones[Fecha],"<="&'Configuración'!$C$8)-SUMIFS(tOperaciones[Importe],tOperaciones[Producto],B39,tOperaciones[Tipo],"Venta",tOperaciones[Fecha],">="&F39,tOperaciones[Fecha],"<="&'Configuración'!$C$8)) | K39: =IF(OR(B39="",COUNT(I39)=0),"",IF(I39=0,0,IF(COUNTIFS(tPrecios[Producto],B39,tPrecios[Fecha],"<="&'Configuración'!$C$8)=0,"",I39*SUMIFS(tPrecios[VL EUR],tPrecios[Producto],B39,tPrecios[Fecha],MAXIFS(tPrecios[Fecha],tPrecios[Producto],B39,tPrecios[Fecha],"<="&'Configuración'!$C$8))))) | L39: =IF(OR(B39="",COUNT(K39)=0),"",K39-J39+SUMIFS(tOperaciones[Importe],tOperaciones[Producto],B39,tOperaciones[Tipo],"Cobro",tOperaciones[Fecha],">="&F39,tOperaciones[Fecha],"<="&'Configuración'!$C$8)) | M39: =IF(OR(B39="",COUNT(L39)=0,H39+SUMIFS(tOperaciones[Importe],tOperaciones[Producto],B39,tOperaciones[Tipo],"Compra",tOperaciones[Fecha],"<="&'Configuración'!$C$8)=0),"",L39/(H39+SUMIFS(tOperaciones[Importe],tOperaciones[Producto],B39,tOperaciones[Tipo],"Compra",tOperaciones[Fecha],"<="&'Configuración'!$C$8))) | N39: =IF(OR(B39="",COUNT(K39)=0,COUNT(tProductos[Valor])<>COUNTA(tProductos[ID]),SUM(tProductos[Valor])=0),"",K39/SUM(tProductos[Valor]))
I40: =IF(OR(B40="",'Configuración'!$C$8<F40),"",G40+SUMIFS(tOperaciones[Participaciones],tOperaciones[Producto],B40,tOperaciones[Tipo],"Compra",tOperaciones[Fecha],">="&F40,tOperaciones[Fecha],"<="&'Configuración'!$C$8)-SUMIFS(tOperaciones[Participaciones],tOperaciones[Producto],B40,tOperaciones[Tipo],"Venta",tOperaciones[Fecha],">="&F40,tOperaciones[Fecha],"<="&'Configuración'!$C$8)) | J40: =IF(OR(B40="",'Configuración'!$C$8<F40),"",H40+SUMIFS(tOperaciones[Importe],tOperaciones[Producto],B40,tOperaciones[Tipo],"Compra",tOperaciones[Fecha],">="&F40,tOperaciones[Fecha],"<="&'Configuración'!$C$8)-SUMIFS(tOperaciones[Importe],tOperaciones[Producto],B40,tOperaciones[Tipo],"Venta",tOperaciones[Fecha],">="&F40,tOperaciones[Fecha],"<="&'Configuración'!$C$8)) | K40: =IF(OR(B40="",COUNT(I40)=0),"",IF(I40=0,0,IF(COUNTIFS(tPrecios[Producto],B40,tPrecios[Fecha],"<="&'Configuración'!$C$8)=0,"",I40*SUMIFS(tPrecios[VL EUR],tPrecios[Producto],B40,tPrecios[Fecha],MAXIFS(tPrecios[Fecha],tPrecios[Producto],B40,tPrecios[Fecha],"<="&'Configuración'!$C$8))))) | L40: =IF(OR(B40="",COUNT(K40)=0),"",K40-J40+SUMIFS(tOperaciones[Importe],tOperaciones[Producto],B40,tOperaciones[Tipo],"Cobro",tOperaciones[Fecha],">="&F40,tOperaciones[Fecha],"<="&'Configuración'!$C$8)) | M40: =IF(OR(B40="",COUNT(L40)=0,H40+SUMIFS(tOperaciones[Importe],tOperaciones[Producto],B40,tOperaciones[Tipo],"Compra",tOperaciones[Fecha],"<="&'Configuración'!$C$8)=0),"",L40/(H40+SUMIFS(tOperaciones[Importe],tOperaciones[Producto],B40,tOperaciones[Tipo],"Compra",tOperaciones[Fecha],"<="&'Configuración'!$C$8))) | N40: =IF(OR(B40="",COUNT(K40)=0,COUNT(tProductos[Valor])<>COUNTA(tProductos[ID]),SUM(tProductos[Valor])=0),"",K40/SUM(tProductos[Valor]))
I41: =IF(OR(B41="",'Configuración'!$C$8<F41),"",G41+SUMIFS(tOperaciones[Participaciones],tOperaciones[Producto],B41,tOperaciones[Tipo],"Compra",tOperaciones[Fecha],">="&F41,tOperaciones[Fecha],"<="&'Configuración'!$C$8)-SUMIFS(tOperaciones[Participaciones],tOperaciones[Producto],B41,tOperaciones[Tipo],"Venta",tOperaciones[Fecha],">="&F41,tOperaciones[Fecha],"<="&'Configuración'!$C$8)) | J41: =IF(OR(B41="",'Configuración'!$C$8<F41),"",H41+SUMIFS(tOperaciones[Importe],tOperaciones[Producto],B41,tOperaciones[Tipo],"Compra",tOperaciones[Fecha],">="&F41,tOperaciones[Fecha],"<="&'Configuración'!$C$8)-SUMIFS(tOperaciones[Importe],tOperaciones[Producto],B41,tOperaciones[Tipo],"Venta",tOperaciones[Fecha],">="&F41,tOperaciones[Fecha],"<="&'Configuración'!$C$8)) | K41: =IF(OR(B41="",COUNT(I41)=0),"",IF(I41=0,0,IF(COUNTIFS(tPrecios[Producto],B41,tPrecios[Fecha],"<="&'Configuración'!$C$8)=0,"",I41*SUMIFS(tPrecios[VL EUR],tPrecios[Producto],B41,tPrecios[Fecha],MAXIFS(tPrecios[Fecha],tPrecios[Producto],B41,tPrecios[Fecha],"<="&'Configuración'!$C$8))))) | L41: =IF(OR(B41="",COUNT(K41)=0),"",K41-J41+SUMIFS(tOperaciones[Importe],tOperaciones[Producto],B41,tOperaciones[Tipo],"Cobro",tOperaciones[Fecha],">="&F41,tOperaciones[Fecha],"<="&'Configuración'!$C$8)) | M41: =IF(OR(B41="",COUNT(L41)=0,H41+SUMIFS(tOperaciones[Importe],tOperaciones[Producto],B41,tOperaciones[Tipo],"Compra",tOperaciones[Fecha],"<="&'Configuración'!$C$8)=0),"",L41/(H41+SUMIFS(tOperaciones[Importe],tOperaciones[Producto],B41,tOperaciones[Tipo],"Compra",tOperaciones[Fecha],"<="&'Configuración'!$C$8))) | N41: =IF(OR(B41="",COUNT(K41)=0,COUNT(tProductos[Valor])<>COUNTA(tProductos[ID]),SUM(tProductos[Valor])=0),"",K41/SUM(tProductos[Valor]))
... I149: =IF(OR(B149="",'Configuración'!$C$8<F149),"",G149+SUMIFS(tOperaciones[Participaciones],tOperaciones[Producto],B149,tOperaciones[Tipo],"Compra",tOperaciones[Fecha],">="&F149,tOperaciones[Fecha],"<="&'Configuración'!$C$8)-SUMIFS(tOperaciones[Participaciones],tOperaciones[Producto],B149,tOperaciones[Tipo],"Venta",tOperaciones[Fecha],">="&F149,tOperaciones[Fecha],"<="&'Configuración'!$C$8)) | J149: =IF(OR(B149="",'Configuración'!$C$8<F149),"",H149+SUMIFS(tOperaciones[Importe],tOperaciones[Producto],B149,tOperaciones[Tipo],"Compra",tOperaciones[Fecha],">="&F149,tOperaciones[Fecha],"<="&'Configuración'!$C$8)-SUMIFS(tOperaciones[Importe],tOperaciones[Producto],B149,tOperaciones[Tipo],"Venta",tOperaciones[Fecha],">="&F149,tOperaciones[Fecha],"<="&'Configuración'!$C$8)) | K149: =IF(OR(B149="",COUNT(I149)=0),"",IF(I149=0,0,IF(COUNTIFS(tPrecios[Producto],B149,tPrecios[Fecha],"<="&'Configuración'!$C$8)=0,"",I149*SUMIFS(tPrecios[VL EUR],tPrecios[Producto],B149,tPrecios[Fecha],MAXIFS(tPrecios[Fecha],tPrecios[Producto],B149,tPrecios[Fecha],"<="&'Configuración'!$C$8))))) | L149: =IF(OR(B149="",COUNT(K149)=0),"",K149-J149+SUMIFS(tOperaciones[Importe],tOperaciones[Producto],B149,tOperaciones[Tipo],"Cobro",tOperaciones[Fecha],">="&F149,tOperaciones[Fecha],"<="&'Configuración'!$C$8)) | M149: =IF(OR(B149="",COUNT(L149)=0,H149+SUMIFS(tOperaciones[Importe],tOperaciones[Producto],B149,tOperaciones[Tipo],"Compra",tOperaciones[Fecha],"<="&'Configuración'!$C$8)=0),"",L149/(H149+SUMIFS(tOperaciones[Importe],tOperaciones[Producto],B149,tOperaciones[Tipo],"Compra",tOperaciones[Fecha],"<="&'Configuración'!$C$8))) | N149: =IF(OR(B149="",COUNT(K149)=0,COUNT(tProductos[Valor])<>COUNTA(tProductos[ID]),SUM(tProductos[Valor])=0),"",K149/SUM(tProductos[Valor]))
B153: Compras, ventas y cobros
B155: ID | C155: Fecha | D155: Producto | E155: Tipo | F155: Participaciones | G155: Precio | H155: Comisión | I155: Retención | J155: Importe | K155: Movimiento
J156: =IF(B156="","",IF(E156="Compra",F156*G156+H156,IF(E156="Venta",F156*G156-H156-I156,IF(E156="Cobro",G156-H156-I156,0))))
J157: =IF(B157="","",IF(E157="Compra",F157*G157+H157,IF(E157="Venta",F157*G157-H157-I157,IF(E157="Cobro",G157-H157-I157,0))))
J158: =IF(B158="","",IF(E158="Compra",F158*G158+H158,IF(E158="Venta",F158*G158-H158-I158,IF(E158="Cobro",G158-H158-I158,0))))
J159: =IF(B159="","",IF(E159="Compra",F159*G159+H159,IF(E159="Venta",F159*G159-H159-I159,IF(E159="Cobro",G159-H159-I159,0))))
J160: =IF(B160="","",IF(E160="Compra",F160*G160+H160,IF(E160="Venta",F160*G160-H160-I160,IF(E160="Cobro",G160-H160-I160,0))))
J161: =IF(B161="","",IF(E161="Compra",F161*G161+H161,IF(E161="Venta",F161*G161-H161-I161,IF(E161="Cobro",G161-H161-I161,0))))
J162: =IF(B162="","",IF(E162="Compra",F162*G162+H162,IF(E162="Venta",F162*G162-H162-I162,IF(E162="Cobro",G162-H162-I162,0))))
J163: =IF(B163="","",IF(E163="Compra",F163*G163+H163,IF(E163="Venta",F163*G163-H163-I163,IF(E163="Cobro",G163-H163-I163,0))))
J164: =IF(B164="","",IF(E164="Compra",F164*G164+H164,IF(E164="Venta",F164*G164-H164-I164,IF(E164="Cobro",G164-H164-I164,0))))
J165: =IF(B165="","",IF(E165="Compra",F165*G165+H165,IF(E165="Venta",F165*G165-H165-I165,IF(E165="Cobro",G165-H165-I165,0))))
J166: =IF(B166="","",IF(E166="Compra",F166*G166+H166,IF(E166="Venta",F166*G166-H166-I166,IF(E166="Cobro",G166-H166-I166,0))))
J167: =IF(B167="","",IF(E167="Compra",F167*G167+H167,IF(E167="Venta",F167*G167-H167-I167,IF(E167="Cobro",G167-H167-I167,0))))
... J285: =IF(B285="","",IF(E285="Compra",F285*G285+H285,IF(E285="Venta",F285*G285-H285-I285,IF(E285="Cobro",G285-H285-I285,0))))
B289: Valores liquidativos
B291: Producto | C291: Fecha | D291: VL EUR | E291: Fuente
B925: Evolución mensual
B927: Mes | C927: Capital invertido | D927: Valor de mercado | E927: Resultado
B928: =IF(EDATE(DATE(YEAR(IF(COUNT(Inversiones!$F$30:$F$149)=0,'Configuración'!$C$8,MIN(Inversiones!$F$30:$F$149))),MONTH(IF(COUNT(Inversiones!$F$30:$F$149)=0,'Configuración'!$C$8,MIN(Inversiones!$F$30:$F$149))),1),0)>EOMONTH('Configuración'!$C$8,0),"",TEXT(EDATE(DATE(YEAR(IF(COUNT(Inversiones!$F$30:$F$149)=0,'Configuración'!$C$8,MIN(Inversiones!$F$30:$F$149))),MONTH(IF(COUNT(Inversiones!$F$30:$F$149)=0,'Configuración'!$C$8,MIN(Inversiones!$F$30:$F$149))),1),0),"mmm yyyy")) -> ene 2026 | C928: =IF(EDATE(DATE(YEAR(IF(COUNT(Inversiones!$F$30:$F$149)=0,'Configuración'!$C$8,MIN(Inversiones!$F$30:$F$149))),MONTH(IF(COUNT(Inversiones!$F$30:$F$149)=0,'Configuración'!$C$8,MIN(Inversiones!$F$30:$F$149))),1),0)>EOMONTH('Configuración'!$C$8,0),"",IF(Inversiones!$D$4="Todos",IF(SUMIFS('Cálculos'!$E$278:$E$334,'Cálculos'!$B$278:$B$334,EDATE(DATE(YEAR(IF(COUNT(Inversiones!$F$30:$F$149)=0,'Configuración'!$C$8,MIN(Inversiones!$F$30:$F$149))),MONTH(IF(COUNT(Inversiones!$F$30:$F$149)=0,'Configuración'!$C$8,MIN(Inversiones!$F$30:$F$149))),1),0))=COUNTA(Inversiones!$B$30:$B$149),SUMIFS('Cálculos'!$G$278:$G$334,'Cálculos'!$B$278:$B$334,EDATE(DATE(YEAR(IF(COUNT(Inversiones!$F$30:$F$149)=0,'Configuración'!$C$8,MIN(Inversiones!$F$30:$F$149))),MONTH(IF(COUNT(Inversiones!$F$30:$F$149)=0,'Configuración'!$C$8,MIN(Inversiones!$F$30:$F$149))),1),0)),""),IF(SUMIFS('Cálculos'!$E$278:$E$334,'Cálculos'!$B$278:$B$334,EDATE(DATE(YEAR(IF(COUNT(Inversiones!$F$30:$F$149)=0,'Configuración'!$C$8,MIN(Inversiones!$F$30:$F$149))),MONTH(IF(COUNT(Inversiones!$F$30:$F$149)=0,'Configuración'!$C$8,MIN(Inversiones!$F$30:$F$149))),1),0),'Cálculos'!$C$278:$C$334,'Cálculos'!$I$4)=1,SUMIFS('Cálculos'!$G$278:$G$334,'Cálculos'!$B$278:$B$334,EDATE(DATE(YEAR(IF(COUNT(Inversiones!$F$30:$F$149)=0,'Configuración'!$C$8,MIN(Inversiones!$F$30:$F$149))),MONTH(IF(COUNT(Inversiones!$F$30:$F$149)=0,'Configuración'!$C$8,MIN(Inversiones!$F$30:$F$149))),1),0),'Cálculos'!$C$278:$C$334,'Cálculos'!$I$4),""))) -> 0 | D928: =IF(EDATE(DATE(YEAR(IF(COUNT(Inversiones!$F$30:$F$149)=0,'Configuración'!$C$8,MIN(Inversiones!$F$30:$F$149))),MONTH(IF(COUNT(Inversiones!$F$30:$F$149)=0,'Configuración'!$C$8,MIN(Inversiones!$F$30:$F$149))),1),0)>EOMONTH('Configuración'!$C$8,0),"",IF(Inversiones!$D$4="Todos",IF(SUMIFS('Cálculos'!$K$278:$K$334,'Cálculos'!$B$278:$B$334,EDATE(DATE(YEAR(IF(COUNT(Inversiones!$F$30:$F$149)=0,'Configuración'!$C$8,MIN(Inversiones!$F$30:$F$149))),MONTH(IF(COUNT(Inversiones!$F$30:$F$149)=0,'Configuración'!$C$8,MIN(Inversiones!$F$30:$F$149))),1),0))=COUNTA(Inversiones!$B$30:$B$149),SUMIFS('Cálculos'!$J$278:$J$334,'Cálculos'!$B$278:$B$334,EDATE(DATE(YEAR(IF(COUNT(Inversiones!$F$30:$F$149)=0,'Configuración'!$C$8,MIN(Inversiones!$F$30:$F$149))),MONTH(IF(COUNT(Inversiones!$F$30:$F$149)=0,'Configuración'!$C$8,MIN(Inversiones!$F$30:$F$149))),1),0)),""),IF(SUMIFS('Cálculos'!$K$278:$K$334,'Cálculos'!$B$278:$B$334,EDATE(DATE(YEAR(IF(COUNT(Inversiones!$F$30:$F$149)=0,'Configuración'!$C$8,MIN(Inversiones!$F$30:$F$149))),MONTH(IF(COUNT(Inversiones!$F$30:$F$149)=0,'Configuración'!$C$8,MIN(Inversiones!$F$30:$F$149))),1),0),'Cálculos'!$C$278:$C$334,'Cálculos'!$I$4)=1,SUMIFS('Cálculos'!$J$278:$J$334,'Cálculos'!$B$278:$B$334,EDATE(DATE(YEAR(IF(COUNT(Inversiones!$F$30:$F$149)=0,'Configuración'!$C$8,MIN(Inversiones!$F$30:$F$149))),MONTH(IF(COUNT(Inversiones!$F$30:$F$149)=0,'Configuración'!$C$8,MIN(Inversiones!$F$30:$F$149))),1),0),'Cálculos'!$C$278:$C$334,'Cálculos'!$I$4),""))) -> 0 | E928: =IF(COUNT(C928,D928)<2,"",D928-C928) -> 0
B929: =IF(EDATE(DATE(YEAR(IF(COUNT(Inversiones!$F$30:$F$149)=0,'Configuración'!$C$8,MIN(Inversiones!$F$30:$F$149))),MONTH(IF(COUNT(Inversiones!$F$30:$F$149)=0,'Configuración'!$C$8,MIN(Inversiones!$F$30:$F$149))),1),1)>EOMONTH('Configuración'!$C$8,0),"",TEXT(EDATE(DATE(YEAR(IF(COUNT(Inversiones!$F$30:$F$149)=0,'Configuración'!$C$8,MIN(Inversiones!$F$30:$F$149))),MONTH(IF(COUNT(Inversiones!$F$30:$F$149)=0,'Configuración'!$C$8,MIN(Inversiones!$F$30:$F$149))),1),1),"mmm yyyy")) | C929: =IF(EDATE(DATE(YEAR(IF(COUNT(Inversiones!$F$30:$F$149)=0,'Configuración'!$C$8,MIN(Inversiones!$F$30:$F$149))),MONTH(IF(COUNT(Inversiones!$F$30:$F$149)=0,'Configuración'!$C$8,MIN(Inversiones!$F$30:$F$149))),1),1)>EOMONTH('Configuración'!$C$8,0),"",IF(Inversiones!$D$4="Todos",IF(SUMIFS('Cálculos'!$E$278:$E$334,'Cálculos'!$B$278:$B$334,EDATE(DATE(YEAR(IF(COUNT(Inversiones!$F$30:$F$149)=0,'Configuración'!$C$8,MIN(Inversiones!$F$30:$F$149))),MONTH(IF(COUNT(Inversiones!$F$30:$F$149)=0,'Configuración'!$C$8,MIN(Inversiones!$F$30:$F$149))),1),1))=COUNTA(Inversiones!$B$30:$B$149),SUMIFS('Cálculos'!$G$278:$G$334,'Cálculos'!$B$278:$B$334,EDATE(DATE(YEAR(IF(COUNT(Inversiones!$F$30:$F$149)=0,'Configuración'!$C$8,MIN(Inversiones!$F$30:$F$149))),MONTH(IF(COUNT(Inversiones!$F$30:$F$149)=0,'Configuración'!$C$8,MIN(Inversiones!$F$30:$F$149))),1),1)),""),IF(SUMIFS('Cálculos'!$E$278:$E$334,'Cálculos'!$B$278:$B$334,EDATE(DATE(YEAR(IF(COUNT(Inversiones!$F$30:$F$149)=0,'Configuración'!$C$8,MIN(Inversiones!$F$30:$F$149))),MONTH(IF(COUNT(Inversiones!$F$30:$F$149)=0,'Configuración'!$C$8,MIN(Inversiones!$F$30:$F$149))),1),1),'Cálculos'!$C$278:$C$334,'Cálculos'!$I$4)=1,SUMIFS('Cálculos'!$G$278:$G$334,'Cálculos'!$B$278:$B$334,EDATE(DATE(YEAR(IF(COUNT(Inversiones!$F$30:$F$149)=0,'Configuración'!$C$8,MIN(Inversiones!$F$30:$F$149))),MONTH(IF(COUNT(Inversiones!$F$30:$F$149)=0,'Configuración'!$C$8,MIN(Inversiones!$F$30:$F$149))),1),1),'Cálculos'!$C$278:$C$334,'Cálculos'!$I$4),""))) | D929: =IF(EDATE(DATE(YEAR(IF(COUNT(Inversiones!$F$30:$F$149)=0,'Configuración'!$C$8,MIN(Inversiones!$F$30:$F$149))),MONTH(IF(COUNT(Inversiones!$F$30:$F$149)=0,'Configuración'!$C$8,MIN(Inversiones!$F$30:$F$149))),1),1)>EOMONTH('Configuración'!$C$8,0),"",IF(Inversiones!$D$4="Todos",IF(SUMIFS('Cálculos'!$K$278:$K$334,'Cálculos'!$B$278:$B$334,EDATE(DATE(YEAR(IF(COUNT(Inversiones!$F$30:$F$149)=0,'Configuración'!$C$8,MIN(Inversiones!$F$30:$F$149))),MONTH(IF(COUNT(Inversiones!$F$30:$F$149)=0,'Configuración'!$C$8,MIN(Inversiones!$F$30:$F$149))),1),1))=COUNTA(Inversiones!$B$30:$B$149),SUMIFS('Cálculos'!$J$278:$J$334,'Cálculos'!$B$278:$B$334,EDATE(DATE(YEAR(IF(COUNT(Inversiones!$F$30:$F$149)=0,'Configuración'!$C$8,MIN(Inversiones!$F$30:$F$149))),MONTH(IF(COUNT(Inversiones!$F$30:$F$149)=0,'Configuración'!$C$8,MIN(Inversiones!$F$30:$F$149))),1),1)),""),IF(SUMIFS('Cálculos'!$K$278:$K$334,'Cálculos'!$B$278:$B$334,EDATE(DATE(YEAR(IF(COUNT(Inversiones!$F$30:$F$149)=0,'Configuración'!$C$8,MIN(Inversiones!$F$30:$F$149))),MONTH(IF(COUNT(Inversiones!$F$30:$F$149)=0,'Configuración'!$C$8,MIN(Inversiones!$F$30:$F$149))),1),1),'Cálculos'!$C$278:$C$334,'Cálculos'!$I$4)=1,SUMIFS('Cálculos'!$J$278:$J$334,'Cálculos'!$B$278:$B$334,EDATE(DATE(YEAR(IF(COUNT(Inversiones!$F$30:$F$149)=0,'Configuración'!$C$8,MIN(Inversiones!$F$30:$F$149))),MONTH(IF(COUNT(Inversiones!$F$30:$F$149)=0,'Configuración'!$C$8,MIN(Inversiones!$F$30:$F$149))),1),1),'Cálculos'!$C$278:$C$334,'Cálculos'!$I$4),""))) | E929: =IF(COUNT(C929,D929)<2,"",D929-C929)
B930: =IF(EDATE(DATE(YEAR(IF(COUNT(Inversiones!$F$30:$F$149)=0,'Configuración'!$C$8,MIN(Inversiones!$F$30:$F$149))),MONTH(IF(COUNT(Inversiones!$F$30:$F$149)=0,'Configuración'!$C$8,MIN(Inversiones!$F$30:$F$149))),1),2)>EOMONTH('Configuración'!$C$8,0),"",TEXT(EDATE(DATE(YEAR(IF(COUNT(Inversiones!$F$30:$F$149)=0,'Configuración'!$C$8,MIN(Inversiones!$F$30:$F$149))),MONTH(IF(COUNT(Inversiones!$F$30:$F$149)=0,'Configuración'!$C$8,MIN(Inversiones!$F$30:$F$149))),1),2),"mmm yyyy")) | C930: =IF(EDATE(DATE(YEAR(IF(COUNT(Inversiones!$F$30:$F$149)=0,'Configuración'!$C$8,MIN(Inversiones!$F$30:$F$149))),MONTH(IF(COUNT(Inversiones!$F$30:$F$149)=0,'Configuración'!$C$8,MIN(Inversiones!$F$30:$F$149))),1),2)>EOMONTH('Configuración'!$C$8,0),"",IF(Inversiones!$D$4="Todos",IF(SUMIFS('Cálculos'!$E$278:$E$334,'Cálculos'!$B$278:$B$334,EDATE(DATE(YEAR(IF(COUNT(Inversiones!$F$30:$F$149)=0,'Configuración'!$C$8,MIN(Inversiones!$F$30:$F$149))),MONTH(IF(COUNT(Inversiones!$F$30:$F$149)=0,'Configuración'!$C$8,MIN(Inversiones!$F$30:$F$149))),1),2))=COUNTA(Inversiones!$B$30:$B$149),SUMIFS('Cálculos'!$G$278:$G$334,'Cálculos'!$B$278:$B$334,EDATE(DATE(YEAR(IF(COUNT(Inversiones!$F$30:$F$149)=0,'Configuración'!$C$8,MIN(Inversiones!$F$30:$F$149))),MONTH(IF(COUNT(Inversiones!$F$30:$F$149)=0,'Configuración'!$C$8,MIN(Inversiones!$F$30:$F$149))),1),2)),""),IF(SUMIFS('Cálculos'!$E$278:$E$334,'Cálculos'!$B$278:$B$334,EDATE(DATE(YEAR(IF(COUNT(Inversiones!$F$30:$F$149)=0,'Configuración'!$C$8,MIN(Inversiones!$F$30:$F$149))),MONTH(IF(COUNT(Inversiones!$F$30:$F$149)=0,'Configuración'!$C$8,MIN(Inversiones!$F$30:$F$149))),1),2),'Cálculos'!$C$278:$C$334,'Cálculos'!$I$4)=1,SUMIFS('Cálculos'!$G$278:$G$334,'Cálculos'!$B$278:$B$334,EDATE(DATE(YEAR(IF(COUNT(Inversiones!$F$30:$F$149)=0,'Configuración'!$C$8,MIN(Inversiones!$F$30:$F$149))),MONTH(IF(COUNT(Inversiones!$F$30:$F$149)=0,'Configuración'!$C$8,MIN(Inversiones!$F$30:$F$149))),1),2),'Cálculos'!$C$278:$C$334,'Cálculos'!$I$4),""))) | D930: =IF(EDATE(DATE(YEAR(IF(COUNT(Inversiones!$F$30:$F$149)=0,'Configuración'!$C$8,MIN(Inversiones!$F$30:$F$149))),MONTH(IF(COUNT(Inversiones!$F$30:$F$149)=0,'Configuración'!$C$8,MIN(Inversiones!$F$30:$F$149))),1),2)>EOMONTH('Configuración'!$C$8,0),"",IF(Inversiones!$D$4="Todos",IF(SUMIFS('Cálculos'!$K$278:$K$334,'Cálculos'!$B$278:$B$334,EDATE(DATE(YEAR(IF(COUNT(Inversiones!$F$30:$F$149)=0,'Configuración'!$C$8,MIN(Inversiones!$F$30:$F$149))),MONTH(IF(COUNT(Inversiones!$F$30:$F$149)=0,'Configuración'!$C$8,MIN(Inversiones!$F$30:$F$149))),1),2))=COUNTA(Inversiones!$B$30:$B$149),SUMIFS('Cálculos'!$J$278:$J$334,'Cálculos'!$B$278:$B$334,EDATE(DATE(YEAR(IF(COUNT(Inversiones!$F$30:$F$149)=0,'Configuración'!$C$8,MIN(Inversiones!$F$30:$F$149))),MONTH(IF(COUNT(Inversiones!$F$30:$F$149)=0,'Configuración'!$C$8,MIN(Inversiones!$F$30:$F$149))),1),2)),""),IF(SUMIFS('Cálculos'!$K$278:$K$334,'Cálculos'!$B$278:$B$334,EDATE(DATE(YEAR(IF(COUNT(Inversiones!$F$30:$F$149)=0,'Configuración'!$C$8,MIN(Inversiones!$F$30:$F$149))),MONTH(IF(COUNT(Inversiones!$F$30:$F$149)=0,'Configuración'!$C$8,MIN(Inversiones!$F$30:$F$149))),1),2),'Cálculos'!$C$278:$C$334,'Cálculos'!$I$4)=1,SUMIFS('Cálculos'!$J$278:$J$334,'Cálculos'!$B$278:$B$334,EDATE(DATE(YEAR(IF(COUNT(Inversiones!$F$30:$F$149)=0,'Configuración'!$C$8,MIN(Inversiones!$F$30:$F$149))),MONTH(IF(COUNT(Inversiones!$F$30:$F$149)=0,'Configuración'!$C$8,MIN(Inversiones!$F$30:$F$149))),1),2),'Cálculos'!$C$278:$C$334,'Cálculos'!$I$4),""))) | E930: =IF(COUNT(C930,D930)<2,"",D930-C930)
...

Sheet Cuentas
B2: Cuentas
B8: Cuenta | C8: Saldo inicial | D8: Saldo real | E8: Fecha saldo | F8: Saldo calculado | H8: ID | I8: Acreedor | J8: Saldo inicial | K8: Saldo pendiente
F9: =IF(B9="","",C9+SUMIFS(tMovimientos[Importe],tMovimientos[Destino],B9,tMovimientos[Fecha],">="&'Configuración'!$C$6,tMovimientos[Fecha],"<="&'Configuración'!$C$7)-SUMIFS(tMovimientos[Importe],tMovimientos[Origen],B9,tMovimientos[Fecha],">="&'Configuración'!$C$6,tMovimientos[Fecha],"<="&'Configuración'!$C$7)) | K9: =IF(H9="","",J9+SUMIFS(tVinculos[Importe],tVinculos[Vinculado a],H9,tVinculos[Tipo],"Préstamo recibido",tVinculos[Fecha],">="&'Configuración'!$C$6,tVinculos[Fecha],"<="&'Configuración'!$C$7)-SUMIFS(tVinculos[Importe],tVinculos[Vinculado a],H9,tVinculos[Tipo],"Devolución deuda",tVinculos[Fecha],">="&'Configuración'!$C$6,tVinculos[Fecha],"<="&'Configuración'!$C$7))
F10: =IF(B10="","",C10+SUMIFS(tMovimientos[Importe],tMovimientos[Destino],B10,tMovimientos[Fecha],">="&'Configuración'!$C$6,tMovimientos[Fecha],"<="&'Configuración'!$C$7)-SUMIFS(tMovimientos[Importe],tMovimientos[Origen],B10,tMovimientos[Fecha],">="&'Configuración'!$C$6,tMovimientos[Fecha],"<="&'Configuración'!$C$7)) | K10: =IF(H10="","",J10+SUMIFS(tVinculos[Importe],tVinculos[Vinculado a],H10,tVinculos[Tipo],"Préstamo recibido",tVinculos[Fecha],">="&'Configuración'!$C$6,tVinculos[Fecha],"<="&'Configuración'!$C$7)-SUMIFS(tVinculos[Importe],tVinculos[Vinculado a],H10,tVinculos[Tipo],"Devolución deuda",tVinculos[Fecha],">="&'Configuración'!$C$6,tVinculos[Fecha],"<="&'Configuración'!$C$7))
F11: =IF(B11="","",C11+SUMIFS(tMovimientos[Importe],tMovimientos[Destino],B11,tMovimientos[Fecha],">="&'Configuración'!$C$6,tMovimientos[Fecha],"<="&'Configuración'!$C$7)-SUMIFS(tMovimientos[Importe],tMovimientos[Origen],B11,tMovimientos[Fecha],">="&'Configuración'!$C$6,tMovimientos[Fecha],"<="&'Configuración'!$C$7)) | K11: =IF(H11="","",J11+SUMIFS(tVinculos[Importe],tVinculos[Vinculado a],H11,tVinculos[Tipo],"Préstamo recibido",tVinculos[Fecha],">="&'Configuración'!$C$6,tVinculos[Fecha],"<="&'Configuración'!$C$7)-SUMIFS(tVinculos[Importe],tVinculos[Vinculado a],H11,tVinculos[Tipo],"Devolución deuda",tVinculos[Fecha],">="&'Configuración'!$C$6,tVinculos[Fecha],"<="&'Configuración'!$C$7))
F12: =IF(B12="","",C12+SUMIFS(tMovimientos[Importe],tMovimientos[Destino],B12,tMovimientos[Fecha],">="&'Configuración'!$C$6,tMovimientos[Fecha],"<="&'Configuración'!$C$7)-SUMIFS(tMovimientos[Importe],tMovimientos[Origen],B12,tMovimientos[Fecha],">="&'Configuración'!$C$6,tMovimientos[Fecha],"<="&'Configuración'!$C$7)) | K12: =IF(H12="","",J12+SUMIFS(tVinculos[Importe],tVinculos[Vinculado a],H12,tVinculos[Tipo],"Préstamo recibido",tVinculos[Fecha],">="&'Configuración'!$C$6,tVinculos[Fecha],"<="&'Configuración'!$C$7)-SUMIFS(tVinculos[Importe],tVinculos[Vinculado a],H12,tVinculos[Tipo],"Devolución deuda",tVinculos[Fecha],">="&'Configuración'!$C$6,tVinculos[Fecha],"<="&'Configuración'!$C$7))
F13: =IF(B13="","",C13+SUMIFS(tMovimientos[Importe],tMovimientos[Destino],B13,tMovimientos[Fecha],">="&'Configuración'!$C$6,tMovimientos[Fecha],"<="&'Configuración'!$C$7)-SUMIFS(tMovimientos[Importe],tMovimientos[Origen],B13,tMovimientos[Fecha],">="&'Configuración'!$C$6,tMovimientos[Fecha],"<="&'Configuración'!$C$7)) | K13: =IF(H13="","",J13+SUMIFS(tVinculos[Importe],tVinculos[Vinculado a],H13,tVinculos[Tipo],"Préstamo recibido",tVinculos[Fecha],">="&'Configuración'!$C$6,tVinculos[Fecha],"<="&'Configuración'!$C$7)-SUMIFS(tVinculos[Importe],tVinculos[Vinculado a],H13,tVinculos[Tipo],"Devolución deuda",tVinculos[Fecha],">="&'Configuración'!$C$6,tVinculos[Fecha],"<="&'Configuración'!$C$7))
F14: =IF(B14="","",C14+SUMIFS(tMovimientos[Importe],tMovimientos[Destino],B14,tMovimientos[Fecha],">="&'Configuración'!$C$6,tMovimientos[Fecha],"<="&'Configuración'!$C$7)-SUMIFS(tMovimientos[Importe],tMovimientos[Origen],B14,tMovimientos[Fecha],">="&'Configuración'!$C$6,tMovimientos[Fecha],"<="&'Configuración'!$C$7)) | K14: =IF(H14="","",J14+SUMIFS(tVinculos[Importe],tVinculos[Vinculado a],H14,tVinculos[Tipo],"Préstamo recibido",tVinculos[Fecha],">="&'Configuración'!$C$6,tVinculos[Fecha],"<="&'Configuración'!$C$7)-SUMIFS(tVinculos[Importe],tVinculos[Vinculado a],H14,tVinculos[Tipo],"Devolución deuda",tVinculos[Fecha],">="&'Configuración'!$C$6,tVinculos[Fecha],"<="&'Configuración'!$C$7))
F15: =IF(B15="","",C15+SUMIFS(tMovimientos[Importe],tMovimientos[Destino],B15,tMovimientos[Fecha],">="&'Configuración'!$C$6,tMovimientos[Fecha],"<="&'Configuración'!$C$7)-SUMIFS(tMovimientos[Importe],tMovimientos[Origen],B15,tMovimientos[Fecha],">="&'Configuración'!$C$6,tMovimientos[Fecha],"<="&'Configuración'!$C$7)) | K15: =IF(H15="","",J15+SUMIFS(tVinculos[Importe],tVinculos[Vinculado a],H15,tVinculos[Tipo],"Préstamo recibido",tVinculos[Fecha],">="&'Configuración'!$C$6,tVinculos[Fecha],"<="&'Configuración'!$C$7)-SUMIFS(tVinculos[Importe],tVinculos[Vinculado a],H15,tVinculos[Tipo],"Devolución deuda",tVinculos[Fecha],">="&'Configuración'!$C$6,tVinculos[Fecha],"<="&'Configuración'!$C$7))
F16: =IF(B16="","",C16+SUMIFS(tMovimientos[Importe],tMovimientos[Destino],B16,tMovimientos[Fecha],">="&'Configuración'!$C$6,tMovimientos[Fecha],"<="&'Configuración'!$C$7)-SUMIFS(tMovimientos[Importe],tMovimientos[Origen],B16,tMovimientos[Fecha],">="&'Configuración'!$C$6,tMovimientos[Fecha],"<="&'Configuración'!$C$7)) | K16: =IF(H16="","",J16+SUMIFS(tVinculos[Importe],tVinculos[Vinculado a],H16,tVinculos[Tipo],"Préstamo recibido",tVinculos[Fecha],">="&'Configuración'!$C$6,tVinculos[Fecha],"<="&'Configuración'!$C$7)-SUMIFS(tVinculos[Importe],tVinculos[Vinculado a],H16,tVinculos[Tipo],"Devolución deuda",tVinculos[Fecha],">="&'Configuración'!$C$6,tVinculos[Fecha],"<="&'Configuración'!$C$7))
F17: =IF(B17="","",C17+SUMIFS(tMovimientos[Importe],tMovimientos[Destino],B17,tMovimientos[Fecha],">="&'Configuración'!$C$6,tMovimientos[Fecha],"<="&'Configuración'!$C$7)-SUMIFS(tMovimientos[Importe],tMovimientos[Origen],B17,tMovimientos[Fecha],">="&'Configuración'!$C$6,tMovimientos[Fecha],"<="&'Configuración'!$C$7)) | K17: =IF(H17="","",J17+SUMIFS(tVinculos[Importe],tVinculos[Vinculado a],H17,tVinculos[Tipo],"Préstamo recibido",tVinculos[Fecha],">="&'Configuración'!$C$6,tVinculos[Fecha],"<="&'Configuración'!$C$7)-SUMIFS(tVinculos[Importe],tVinculos[Vinculado a],H17,tVinculos[Tipo],"Devolución deuda",tVinculos[Fecha],">="&'Configuración'!$C$6,tVinculos[Fecha],"<="&'Configuración'!$C$7))
F18: =IF(B18="","",C18+SUMIFS(tMovimientos[Importe],tMovimientos[Destino],B18,tMovimientos[Fecha],">="&'Configuración'!$C$6,tMovimientos[Fecha],"<="&'Configuración'!$C$7)-SUMIFS(tMovimientos[Importe],tMovimientos[Origen],B18,tMovimientos[Fecha],">="&'Configuración'!$C$6,tMovimientos[Fecha],"<="&'Configuración'!$C$7)) | K18: =IF(H18="","",J18+SUMIFS(tVinculos[Importe],tVinculos[Vinculado a],H18,tVinculos[Tipo],"Préstamo recibido",tVinculos[Fecha],">="&'Configuración'!$C$6,tVinculos[Fecha],"<="&'Configuración'!$C$7)-SUMIFS(tVinculos[Importe],tVinculos[Vinculado a],H18,tVinculos[Tipo],"Devolución deuda",tVinculos[Fecha],">="&'Configuración'!$C$6,tVinculos[Fecha],"<="&'Configuración'!$C$7))
F19: =IF(B19="","",C19+SUMIFS(tMovimientos[Importe],tMovimientos[Destino],B19,tMovimientos[Fecha],">="&'Configuración'!$C$6,tMovimientos[Fecha],"<="&'Configuración'!$C$7)-SUMIFS(tMovimientos[Importe],tMovimientos[Origen],B19,tMovimientos[Fecha],">="&'Configuración'!$C$6,tMovimientos[Fecha],"<="&'Configuración'!$C$7)) | K19: =IF(H19="","",J19+SUMIFS(tVinculos[Importe],tVinculos[Vinculado a],H19,tVinculos[Tipo],"Préstamo recibido",tVinculos[Fecha],">="&'Configuración'!$C$6,tVinculos[Fecha],"<="&'Configuración'!$C$7)-SUMIFS(tVinculos[Importe],tVinculos[Vinculado a],H19,tVinculos[Tipo],"Devolución deuda",tVinculos[Fecha],">="&'Configuración'!$C$6,tVinculos[Fecha],"<="&'Configuración'!$C$7))
F20: =IF(B20="","",C20+SUMIFS(tMovimientos[Importe],tMovimientos[Destino],B20,tMovimientos[Fecha],">="&'Configuración'!$C$6,tMovimientos[Fecha],"<="&'Configuración'!$C$7)-SUMIFS(tMovimientos[Importe],tMovimientos[Origen],B20,tMovimientos[Fecha],">="&'Configuración'!$C$6,tMovimientos[Fecha],"<="&'Configuración'!$C$7)) | K20: =IF(H20="","",J20+SUMIFS(tVinculos[Importe],tVinculos[Vinculado a],H20,tVinculos[Tipo],"Préstamo recibido",tVinculos[Fecha],">="&'Configuración'!$C$6,tVinculos[Fecha],"<="&'Configuración'!$C$7)-SUMIFS(tVinculos[Importe],tVinculos[Vinculado a],H20,tVinculos[Tipo],"Devolución deuda",tVinculos[Fecha],">="&'Configuración'!$C$6,tVinculos[Fecha],"<="&'Configuración'!$C$7))
... F128: =IF(B128="","",C128+SUMIFS(tMovimientos[Importe],tMovimientos[Destino],B128,tMovimientos[Fecha],">="&'Configuración'!$C$6,tMovimientos[Fecha],"<="&'Configuración'!$C$7)-SUMIFS(tMovimientos[Importe],tMovimientos[Origen],B128,tMovimientos[Fecha],">="&'Configuración'!$C$6,tMovimientos[Fecha],"<="&'Configuración'!$C$7)) | K128: =IF(H128="","",J128+SUMIFS(tVinculos[Importe],tVinculos[Vinculado a],H128,tVinculos[Tipo],"Préstamo recibido",tVinculos[Fecha],">="&'Configuración'!$C$6,tVinculos[Fecha],"<="&'Configuración'!$C$7)-SUMIFS(tVinculos[Importe],tVinculos[Vinculado a],H128,tVinculos[Tipo],"Devolución deuda",tVinculos[Fecha],">="&'Configuración'!$C$6,tVinculos[Fecha],"<="&'Configuración'!$C$7))
B132: Relaciones
B134: Movimiento | C134: Vinculado a | D134: Fecha | E134: Tipo | F134: Importe
D135: =IF(B135="","",SUMIFS(tMovimientos[Fecha],tMovimientos[ID],B135)) | E135: {=IF(B135="","",INDEX(tMovimientos[Tipo],MATCH(B135,tMovimientos[ID],0)))} | F135: =IF(B135="","",SUMIFS(tMovimientos[Importe],tMovimientos[ID],B135))
D136: =IF(B136="","",SUMIFS(tMovimientos[Fecha],tMovimientos[ID],B136)) | E136: {=IF(B136="","",INDEX(tMovimientos[Tipo],MATCH(B136,tMovimientos[ID],0)))} | F136: =IF(B136="","",SUMIFS(tMovimientos[Importe],tMovimientos[ID],B136))
D137: =IF(B137="","",SUMIFS(tMovimientos[Fecha],tMovimientos[ID],B137)) | E137: {=IF(B137="","",INDEX(tMovimientos[Tipo],MATCH(B137,tMovimientos[ID],0)))} | F137: =IF(B137="","",SUMIFS(tMovimientos[Importe],tMovimientos[ID],B137))
D138: =IF(B138="","",SUMIFS(tMovimientos[Fecha],tMovimientos[ID],B138)) | E138: {=IF(B138="","",INDEX(tMovimientos[Tipo],MATCH(B138,tMovimientos[ID],0)))} | F138: =IF(B138="","",SUMIFS(tMovimientos[Importe],tMovimientos[ID],B138))
D139: =IF(B139="","",SUMIFS(tMovimientos[Fecha],tMovimientos[ID],B139)) | E139: {=IF(B139="","",INDEX(tMovimientos[Tipo],MATCH(B139,tMovimientos[ID],0)))} | F139: =IF(B139="","",SUMIFS(tMovimientos[Importe],tMovimientos[ID],B139))
D140: =IF(B140="","",SUMIFS(tMovimientos[Fecha],tMovimientos[ID],B140)) | E140: {=IF(B140="","",INDEX(tMovimientos[Tipo],MATCH(B140,tMovimientos[ID],0)))} | F140: =IF(B140="","",SUMIFS(tMovimientos[Importe],tMovimientos[ID],B140))
D141: =IF(B141="","",SUMIFS(tMovimientos[Fecha],tMovimientos[ID],B141)) | E141: {=IF(B141="","",INDEX(tMovimientos[Tipo],MATCH(B141,tMovimientos[ID],0)))} | F141: =IF(B141="","",SUMIFS(tMovimientos[Importe],tMovimientos[ID],B141))
D142: =IF(B142="","",SUMIFS(tMovimientos[Fecha],tMovimientos[ID],B142)) | E142: {=IF(B142="","",INDEX(tMovimientos[Tipo],MATCH(B142,tMovimientos[ID],0)))} | F142: =IF(B142="","",SUMIFS(tMovimientos[Importe],tMovimientos[ID],B142))
D143: =IF(B143="","",SUMIFS(tMovimientos[Fecha],tMovimientos[ID],B143)) | E143: {=IF(B143="","",INDEX(tMovimientos[Tipo],MATCH(B143,tMovimientos[ID],0)))} | F143: =IF(B143="","",SUMIFS(tMovimientos[Importe],tMovimientos[ID],B143))
D144: =IF(B144="","",SUMIFS(tMovimientos[Fecha],tMovimientos[ID],B144)) | E144: {=IF(B144="","",INDEX(tMovimientos[Tipo],MATCH(B144,tMovimientos[ID],0)))} | F144: =IF(B144="","",SUMIFS(tMovimientos[Importe],tMovimientos[ID],B144))
D145: =IF(B145="","",SUMIFS(tMovimientos[Fecha],tMovimientos[ID],B145)) | E145: {=IF(B145="","",INDEX(tMovimientos[Tipo],MATCH(B145,tMovimientos[ID],0)))} | F145: =IF(B145="","",SUMIFS(tMovimientos[Importe],tMovimientos[ID],B145))
D146: =IF(B146="","",SUMIFS(tMovimientos[Fecha],tMovimientos[ID],B146)) | E146: {=IF(B146="","",INDEX(tMovimientos[Tipo],MATCH(B146,tMovimientos[ID],0)))} | F146: =IF(B146="","",SUMIFS(tMovimientos[Importe],tMovimientos[ID],B146))
... D254: =IF(B254="","",SUMIFS(tMovimientos[Fecha],tMovimientos[ID],B254)) | E254: {=IF(B254="","",INDEX(tMovimientos[Tipo],MATCH(B254,tMovimientos[ID],0)))} | F254: =IF(B254="","",SUMIFS(tMovimientos[Importe],tMovimientos[ID],B254))

Sheet Salario
B2: Salario
B8: Movimiento | C8: Fecha cobro | D8: Neto | E8: Bruto | F8: Cotización | G8: IRPF | H8: Otras deducciones
C9: =IF(B9="","",SUMIFS(tMovimientos[Fecha],tMovimientos[ID],B9)) | D9: =IF(B9="","",SUMIFS(tMovimientos[Importe],tMovimientos[ID],B9))
C10: =IF(B10="","",SUMIFS(tMovimientos[Fecha],tMovimientos[ID],B10)) | D10: =IF(B10="","",SUMIFS(tMovimientos[Importe],tMovimientos[ID],B10))
C11: =IF(B11="","",SUMIFS(tMovimientos[Fecha],tMovimientos[ID],B11)) | D11: =IF(B11="","",SUMIFS(tMovimientos[Importe],tMovimientos[ID],B11))
C12: =IF(B12="","",SUMIFS(tMovimientos[Fecha],tMovimientos[ID],B12)) | D12: =IF(B12="","",SUMIFS(tMovimientos[Importe],tMovimientos[ID],B12))
C13: =IF(B13="","",SUMIFS(tMovimientos[Fecha],tMovimientos[ID],B13)) | D13: =IF(B13="","",SUMIFS(tMovimientos[Importe],tMovimientos[ID],B13))
C14: =IF(B14="","",SUMIFS(tMovimientos[Fecha],tMovimientos[ID],B14)) | D14: =IF(B14="","",SUMIFS(tMovimientos[Importe],tMovimientos[ID],B14))
C15: =IF(B15="","",SUMIFS(tMovimientos[Fecha],tMovimientos[ID],B15)) | D15: =IF(B15="","",SUMIFS(tMovimientos[Importe],tMovimientos[ID],B15))
C16: =IF(B16="","",SUMIFS(tMovimientos[Fecha],tMovimientos[ID],B16)) | D16: =IF(B16="","",SUMIFS(tMovimientos[Importe],tMovimientos[ID],B16))
C17: =IF(B17="","",SUMIFS(tMovimientos[Fecha],tMovimientos[ID],B17)) | D17: =IF(B17="","",SUMIFS(tMovimientos[Importe],tMovimientos[ID],B17))
C18: =IF(B18="","",SUMIFS(tMovimientos[Fecha],tMovimientos[ID],B18)) | D18: =IF(B18="","",SUMIFS(tMovimientos[Importe],tMovimientos[ID],B18))
C19: =IF(B19="","",SUMIFS(tMovimientos[Fecha],tMovimientos[ID],B19)) | D19: =IF(B19="","",SUMIFS(tMovimientos[Importe],tMovimientos[ID],B19))
C20: =IF(B20="","",SUMIFS(tMovimientos[Fecha],tMovimientos[ID],B20)) | D20: =IF(B20="","",SUMIFS(tMovimientos[Importe],tMovimientos[ID],B20))
... C128: =IF(B128="","",SUMIFS(tMovimientos[Fecha],tMovimientos[ID],B128)) | D128: =IF(B128="","",SUMIFS(tMovimientos[Importe],tMovimientos[ID],B128))

Sheet Objetivos
B2: Objetivos
B8: ID | C8: Objetivo | D8: Meta | E8: Fecha | F8: Asignado | G8: Pendiente | H8: Avance
F9: =IF(B9="","",SUMIFS(tAsignaciones[Importe],tAsignaciones[Objetivo],B9)) | G9: =IF(B9="","",MAX(0,D9-F9)) | H9: =IF(OR(B9="",D9=0),"",F9/D9)
F10: =IF(B10="","",SUMIFS(tAsignaciones[Importe],tAsignaciones[Objetivo],B10)) | G10: =IF(B10="","",MAX(0,D10-F10)) | H10: =IF(OR(B10="",D10=0),"",F10/D10)
F11: =IF(B11="","",SUMIFS(tAsignaciones[Importe],tAsignaciones[Objetivo],B11)) | G11: =IF(B11="","",MAX(0,D11-F11)) | H11: =IF(OR(B11="",D11=0),"",F11/D11)
F12: =IF(B12="","",SUMIFS(tAsignaciones[Importe],tAsignaciones[Objetivo],B12)) | G12: =IF(B12="","",MAX(0,D12-F12)) | H12: =IF(OR(B12="",D12=0),"",F12/D12)
F13: =IF(B13="","",SUMIFS(tAsignaciones[Importe],tAsignaciones[Objetivo],B13)) | G13: =IF(B13="","",MAX(0,D13-F13)) | H13: =IF(OR(B13="",D13=0),"",F13/D13)
F14: =IF(B14="","",SUMIFS(tAsignaciones[Importe],tAsignaciones[Objetivo],B14)) | G14: =IF(B14="","",MAX(0,D14-F14)) | H14: =IF(OR(B14="",D14=0),"",F14/D14)
F15: =IF(B15="","",SUMIFS(tAsignaciones[Importe],tAsignaciones[Objetivo],B15)) | G15: =IF(B15="","",MAX(0,D15-F15)) | H15: =IF(OR(B15="",D15=0),"",F15/D15)
F16: =IF(B16="","",SUMIFS(tAsignaciones[Importe],tAsignaciones[Objetivo],B16)) | G16: =IF(B16="","",MAX(0,D16-F16)) | H16: =IF(OR(B16="",D16=0),"",F16/D16)
F17: =IF(B17="","",SUMIFS(tAsignaciones[Importe],tAsignaciones[Objetivo],B17)) | G17: =IF(B17="","",MAX(0,D17-F17)) | H17: =IF(OR(B17="",D17=0),"",F17/D17)
F18: =IF(B18="","",SUMIFS(tAsignaciones[Importe],tAsignaciones[Objetivo],B18)) | G18: =IF(B18="","",MAX(0,D18-F18)) | H18: =IF(OR(B18="",D18=0),"",F18/D18)
F19: =IF(B19="","",SUMIFS(tAsignaciones[Importe],tAsignaciones[Objetivo],B19)) | G19: =IF(B19="","",MAX(0,D19-F19)) | H19: =IF(OR(B19="",D19=0),"",F19/D19)
F20: =IF(B20="","",SUMIFS(tAsignaciones[Importe],tAsignaciones[Objetivo],B20)) | G20: =IF(B20="","",MAX(0,D20-F20)) | H20: =IF(OR(B20="",D20=0),"",F20/D20)
... F113: =IF(B113="","",SUMIFS(tAsignaciones[Importe],tAsignaciones[Objetivo],B113)) | G113: =IF(B113="","",MAX(0,D113-F113)) | H113: =IF(OR(B113="",D113=0),"",F113/D113)
B117: Asignaciones
B119: Objetivo | C119: Origen | D119: Importe

Sheet Inflación
B2: Interés compuesto
B6: Capital inicial | H6: Aportado | J6: =IF(COUNT(E6:E10)<5,"",E6+E7*E9*12)
B7: Aportación mensual | H7: Capital final | J7: =IF(COUNT(E6:E10)<5,"",IF('Cálculos'!J4=0,E6+E7*E9*12,E6*(1+'Cálculos'!J4)^(E9*12)+E7*((1+'Cálculos'!J4)^(E9*12)-1)/'Cálculos'!J4))
B8: Rentabilidad anual | H8: En euros de hoy | J8: =IF(COUNT(J7)=0,"",J7/(1+E10)^E9)
B9: Años | H9: Rendimiento | J9: =IF(COUNT(J7)=0,"",J7-J6)
B10: Inflación anual
B16: Año | C16: Aportado | D16: Capital | E16: Capital real
B17: 1 | C17: =IF(OR(COUNT($E$6:$E$10)<5,B17>$E$9),"",$E$6+$E$7*B17*12) | D17: =IF(COUNT(C17)=0,"",IF('Cálculos'!$J$4=0,C17,$E$6*(1+'Cálculos'!$J$4)^(B17*12)+$E$7*((1+'Cálculos'!$J$4)^(B17*12)-1)/'Cálculos'!$J$4)) | E17: =IF(COUNT(D17)=0,"",D17/(1+$E$10)^B17)
B18: 2 | C18: =IF(OR(COUNT($E$6:$E$10)<5,B18>$E$9),"",$E$6+$E$7*B18*12) | D18: =IF(COUNT(C18)=0,"",IF('Cálculos'!$J$4=0,C18,$E$6*(1+'Cálculos'!$J$4)^(B18*12)+$E$7*((1+'Cálculos'!$J$4)^(B18*12)-1)/'Cálculos'!$J$4)) | E18: =IF(COUNT(D18)=0,"",D18/(1+$E$10)^B18)
B19: 3 | C19: =IF(OR(COUNT($E$6:$E$10)<5,B19>$E$9),"",$E$6+$E$7*B19*12) | D19: =IF(COUNT(C19)=0,"",IF('Cálculos'!$J$4=0,C19,$E$6*(1+'Cálculos'!$J$4)^(B19*12)+$E$7*((1+'Cálculos'!$J$4)^(B19*12)-1)/'Cálculos'!$J$4)) | E19: =IF(COUNT(D19)=0,"",D19/(1+$E$10)^B19)
B20: 4 | C20: =IF(OR(COUNT($E$6:$E$10)<5,B20>$E$9),"",$E$6+$E$7*B20*12) | D20: =IF(COUNT(C20)=0,"",IF('Cálculos'!$J$4=0,C20,$E$6*(1+'Cálculos'!$J$4)^(B20*12)+$E$7*((1+'Cálculos'!$J$4)^(B20*12)-1)/'Cálculos'!$J$4)) | E20: =IF(COUNT(D20)=0,"",D20/(1+$E$10)^B20)
B21: 5 | C21: =IF(OR(COUNT($E$6:$E$10)<5,B21>$E$9),"",$E$6+$E$7*B21*12) | D21: =IF(COUNT(C21)=0,"",IF('Cálculos'!$J$4=0,C21,$E$6*(1+'Cálculos'!$J$4)^(B21*12)+$E$7*((1+'Cálculos'!$J$4)^(B21*12)-1)/'Cálculos'!$J$4)) | E21: =IF(COUNT(D21)=0,"",D21/(1+$E$10)^B21)
B22: 6 | C22: =IF(OR(COUNT($E$6:$E$10)<5,B22>$E$9),"",$E$6+$E$7*B22*12) | D22: =IF(COUNT(C22)=0,"",IF('Cálculos'!$J$4=0,C22,$E$6*(1+'Cálculos'!$J$4)^(B22*12)+$E$7*((1+'Cálculos'!$J$4)^(B22*12)-1)/'Cálculos'!$J$4)) | E22: =IF(COUNT(D22)=0,"",D22/(1+$E$10)^B22)
